<?xml version="1.0"?>
<robot name="excavator" xmlns:xacro="http://www.ros.org/wiki/xacro">

  <!-- When true: mock_components/GenericSystem for RViz-only MoveIt (no Gazebo). -->
  <xacro:arg name="use_mock_hardware" default="false"/>

  <xacro:property name="mesh_uri" value="package://excavator_description/meshes"/>

  <!-- Massless root -->
  <link name="base_link"/>

  <!-- BASE (heavier + realistic inertia) -->
  <link name="base">
    <inertial>
      <mass value="300.0"/>
      <origin xyz="0 0 0"/>
      <inertia ixx="80" iyy="80" izz="120" ixy="0" ixz="0" iyz="0"/>
    </inertial>
    <visual>
      <geometry>
        <mesh filename="package://excavator_description/meshes/base.dae"/>
      </geometry>
      <origin xyz="0 0 0"/>
    </visual>
    <collision>
      <geometry>
        <mesh filename="package://excavator_description/meshes/base.dae"/>
      </geometry>
    </collision>
  </link>

  <!-- BODY / TURRET -->
  <link name="body">
    <inertial>
      <mass value="350.0"/>
      <origin xyz="0 0 0"/>
      <inertia ixx="60" iyy="60" izz="70" ixy="0" ixz="0" iyz="0"/>
    </inertial>
    <visual>
      <geometry>
        <mesh filename="package://excavator_description/meshes/body.dae"/>
      </geometry>
      <origin xyz="0 0 0"/>
    </visual>
    <collision>
      <geometry>
        <mesh filename="package://excavator_description/meshes/body.dae"/>
      </geometry>
    </collision>
  </link>

  <!-- ARM1 (boom) -->
  <link name="arm1">
    <inertial>
      <mass value="120.0"/>
      <origin xyz="0 0 0"/>
      <inertia ixx="12" iyy="24" izz="22" ixy="0" ixz="0" iyz="0"/>
    </inertial>
    <visual>
      <geometry>
        <mesh filename="package://excavator_description/meshes/arm1.dae"/>
      </geometry>
      <origin xyz="0 0 0"/>
    </visual>
    <collision>
      <geometry>
        <mesh filename="package://excavator_description/meshes/arm1.dae"/>
      </geometry>
    </collision>
  </link>

  <!-- ARM2 (stick) -->
  <link name="arm2">
    <inertial>
      <mass value="80.0"/>
      <origin xyz="0 0 0"/>
      <inertia ixx="8" iyy="16" izz="14" ixy="0" ixz="0" iyz="0"/>
    </inertial>
    <visual>
      <geometry>
        <mesh filename="package://excavator_description/meshes/arm2.dae"/>
      </geometry>
      <origin xyz="0 0 0"/>
    </visual>
    <collision>
      <geometry>
        <mesh filename="package://excavator_description/meshes/arm2.dae"/>
      </geometry>
    </collision>
  </link>

  <!-- SHOVEL (bucket) -->
  <link name="shovel">
    <inertial>
      <mass value="60.0"/>
      <origin xyz="0 0 0"/>
      <inertia ixx="4" iyy="6" izz="6" ixy="0" ixz="0" iyz="0"/>
    </inertial>
    <visual>
      <geometry>
        <mesh filename="package://excavator_description/meshes/shovel.dae"/>
      </geometry>
      <origin xyz="0 0 0"/>
    </visual>
    <collision>
      <geometry>
        <mesh filename="package://excavator_description/meshes/shovel.dae"/>
      </geometry>
    </collision>
  </link>

  <!-- Sensor links (IMU and 3D LiDAR on body/cab) - visible physical sensor geometry -->
  <link name="sensor_imu_link">
    <inertial>
      <mass value="0.02"/>
      <origin xyz="0 0 0"/>
      <inertia ixx="1e-5" iyy="1e-5" izz="1e-5" ixy="0" ixz="0" iyz="0"/>
    </inertial>
    <visual name="imu_visual">
      <geometry><box size="0.12 0.10 0.03"/></geometry>
      <origin xyz="0 0 0"/>
      <material name="imu_material">
        <color rgba="0.9 0.45 0.1 1"/>
      </material>
    </visual>
    <collision name="imu_collision">
      <geometry><box size="0.12 0.10 0.03"/></geometry>
      <origin xyz="0 0 0"/>
    </collision>
  </link>
  <link name="sensor_lidar_link">
    <inertial>
      <mass value="0.05"/>
      <origin xyz="0 0 0"/>
      <inertia ixx="1e-4" iyy="1e-4" izz="1e-4" ixy="0" ixz="0" iyz="0"/>
    </inertial>
    <visual name="lidar_base">
      <geometry><cylinder radius="0.08" length="0.04"/></geometry>
      <origin xyz="0 0 0" rpy="0 0 0"/>
      <material name="lidar_base_material">
        <color rgba="0.1 0.5 0.85 1"/>
      </material>
    </visual>
    <visual name="lidar_dome">
      <geometry><sphere radius="0.07"/></geometry>
      <origin xyz="0 0 0.05" rpy="0 0 0"/>
      <material name="lidar_dome_material">
        <color rgba="0.2 0.6 0.9 0.95"/>
      </material>
    </visual>
    <collision name="lidar_collision">
      <geometry><cylinder radius="0.08" length="0.12"/></geometry>
      <origin xyz="0 0 0.04" rpy="0 0 0"/>
    </collision>
  </link>

  <!-- Fixed joint between base_link (root) and base -->
  <joint name="base_to_base_link" type="fixed">
    <parent link="base_link"/>
    <child link="base"/>
    <origin xyz="0 0 0" rpy="0 0 0"/>
  </joint>

  <!-- Joints with damping/friction and stronger limits -->
  <!-- Revolute with wide limits (not continuous): MoveIt + JointTrajectoryController validate the
       first waypoint against /joint_states; continuous joints often report large accumulated
       angles while planned trajectories use a different branch → instant "start deviates" abort. -->
  <joint name="body_rotation" type="revolute">
    <parent link="base"/>
    <child link="body"/>
    <axis xyz="0 0 1"/>
    <origin xyz="0.0 0.0 0.6"/>
    <dynamics damping="8.0" friction="0.5"/>
    <limit effort="4000.0" lower="-12.566370614359172" upper="12.566370614359172" velocity="1.5"/>
  </joint>

  <joint name="arm1_rotation" type="revolute">
    <parent link="body"/>
    <child link="arm1"/>
    <axis xyz="0 1 0"/>
    <origin xyz="0.933 -0.134 0.302"/>
    <dynamics damping="10.0" friction="1.5"/>
    <limit effort="4000.0" lower="-1.308" upper="-0.087" velocity="1.0"/>
  </joint>

  <joint name="arm2_rotation" type="revolute">
    <parent link="arm1"/>
    <child link="arm2"/>
    <axis xyz="0 1 0"/>
    <origin xyz="2.586 0 -0.625"/>
    <dynamics damping="8.0" friction="1.2"/>
    <limit effort="3500.0" lower="-2.428" upper="-0.085" velocity="1.0"/>
  </joint>

  <joint name="shovel_rotation" type="revolute">
    <parent link="arm2"/>
    <child link="shovel"/>
    <axis xyz="0 1 0"/>
    <origin xyz="-1.362 0 -0.154"/>
    <dynamics damping="6.0" friction="0.8"/>
    <!-- Upper relaxed toward 0: gz/joint_states often ~-0.01 rad; tight upper=-0.357 made CheckStartStateBounds fail. -->
    <limit effort="3000.0" lower="-2.60" upper="0.35" velocity="1.2"/>
  </joint>

  <!-- Body -> sensor links (fixed, above cab) -->
  <joint name="body_to_imu" type="fixed">
    <parent link="body"/>
    <child link="sensor_imu_link"/>
    <origin xyz="0.3 0 0.25" rpy="0 0 0"/>
  </joint>
  <joint name="body_to_lidar" type="fixed">
    <parent link="body"/>
    <child link="sensor_lidar_link"/>
    <origin xyz="0.35 0 0.4" rpy="0 0 0"/>
  </joint>

  <!-- Mock hardware defaults all states to 0; arm joints must be negative per URDF limits. -->
  <xacro:macro name="excavator_mock_ros2_control_joints">
    <joint name="body_rotation">
      <command_interface name="position"/>
      <state_interface name="position">
        <param name="initial_value">0.0</param>
      </state_interface>
      <state_interface name="velocity"/>
    </joint>
    <joint name="arm1_rotation">
      <command_interface name="position"/>
      <state_interface name="position">
        <param name="initial_value">-0.70</param>
      </state_interface>
      <state_interface name="velocity"/>
    </joint>
    <joint name="arm2_rotation">
      <command_interface name="position"/>
      <state_interface name="position">
        <param name="initial_value">-1.26</param>
      </state_interface>
      <state_interface name="velocity"/>
    </joint>
    <joint name="shovel_rotation">
      <command_interface name="position"/>
      <state_interface name="position">
        <param name="initial_value">-1.12</param>
      </state_interface>
      <state_interface name="velocity"/>
    </joint>
  </xacro:macro>

  <xacro:macro name="excavator_ros2_control_joints">
    <joint name="body_rotation">
      <command_interface name="position"/>
      <state_interface name="position">
        <param name="initial_value">0.0</param>
      </state_interface>
      <state_interface name="velocity"/>
    </joint>
    <joint name="arm1_rotation">
      <command_interface name="position"/>
      <state_interface name="position">
        <param name="initial_value">-0.70</param>
      </state_interface>
      <state_interface name="velocity"/>
    </joint>
    <joint name="arm2_rotation">
      <command_interface name="position"/>
      <state_interface name="position">
        <param name="initial_value">-1.26</param>
      </state_interface>
      <state_interface name="velocity"/>
    </joint>
    <joint name="shovel_rotation">
      <command_interface name="position"/>
      <state_interface name="position">
        <param name="initial_value">-1.12</param>
      </state_interface>
      <state_interface name="velocity"/>
    </joint>
  </xacro:macro>

  <!-- ros2_control: Gazebo sim hardware (default) or mock hardware (RViz-only demo). -->
  <xacro:unless value="$(arg use_mock_hardware)">
    <ros2_control name="GazeboSimSystem" type="system">
      <hardware>
        <plugin>gz_ros2_control/GazeboSimSystem</plugin>
      </hardware>
      <xacro:excavator_ros2_control_joints/>
    </ros2_control>
    <gazebo>
      <plugin filename="libgz_ros2_control-system.so"
              name="gz_ros2_control::GazeboSimROS2ControlPlugin">
        <parameters>$(find excavator_description)/config/controllers.yaml</parameters>
      </plugin>
    </gazebo>
  </xacro:unless>

  <xacro:if value="$(arg use_mock_hardware)">
    <ros2_control name="MockHardwareSystem" type="system">
      <hardware>
        <plugin>mock_components/GenericSystem</plugin>
        <param name="mock_sensor_commands">false</param>
        <param name="position_state_following_offset">0.0</param>
      </hardware>
      <xacro:excavator_mock_ros2_control_joints/>
    </ros2_control>
  </xacro:if>

  <!-- IMU sensor (Gazebo Harmonic); orange so visible in sim -->
  <gazebo reference="sensor_imu_link">
    <material>Gazebo/Orange</material>
    <sensor name="imu_sensor" type="imu">
      <always_on>true</always_on>
      <update_rate>100</update_rate>
      <visualize>true</visualize>
      <topic>/excavator/imu</topic>
      <imu>
        <angular_velocity>
          <x><noise type="gaussian"><mean>0.0</mean><stddev>0.0002</stddev></noise></x>
          <y><noise type="gaussian"><mean>0.0</mean><stddev>0.0002</stddev></noise></y>
          <z><noise type="gaussian"><mean>0.0</mean><stddev>0.0002</stddev></noise></z>
        </angular_velocity>
        <linear_acceleration>
          <x><noise type="gaussian"><mean>0.0</mean><stddev>0.017</stddev></noise></x>
          <y><noise type="gaussian"><mean>0.0</mean><stddev>0.017</stddev></noise></y>
          <z><noise type="gaussian"><mean>0.0</mean><stddev>0.017</stddev></noise></z>
        </linear_acceleration>
      </imu>
    </sensor>
  </gazebo>

  <!-- 3D LiDAR sensor (gpu_lidar, Gazebo Harmonic); blue so visible in sim -->
  <gazebo reference="sensor_lidar_link">
    <material>Gazebo/Blue</material>
    <sensor name="lidar_sensor" type="gpu_lidar">
      <always_on>true</always_on>
      <update_rate>10</update_rate>
      <visualize>true</visualize>
      <topic>/excavator/points</topic>
      <lidar>
        <scan>
          <horizontal>
            <samples>360</samples>
            <resolution>1.0</resolution>
            <min_angle>-3.14159265</min_angle>
            <max_angle>3.14159265</max_angle>
          </horizontal>
          <vertical>
            <samples>32</samples>
            <resolution>1.0</resolution>
            <min_angle>-0.261799</min_angle>
            <max_angle>0.261799</max_angle>
          </vertical>
        </scan>
        <range>
          <min>0.2</min>
          <max>30.0</max>
          <resolution>0.01</resolution>
        </range>
      </lidar>
    </sensor>
  </gazebo>

</robot>

